from django.core.exceptions import ValidationError\nfrom django.db import models\n\nclass UniqueLoginModel(models.Model):\n    login = models.CharField(max_length=10, unique=True)\n\n    def clean(self):\n        # Check if another instance with the same login (case-insensitive) exists\n        model_class = self.__class__\n        if model_class.objects.filter(login__iexact=self.login).exists():\n            raise ValidationError(f'The login "{self.login}" is already in use, case-insensitively.')\n\n    def save(self, *args, **kwargs):\n        # Ensure clean() is called before saving\n        self.full_clean()\n        super().save(*args, **kwargs)